Workbook

Sheet MIS
A1: AWB | B1: Merchant | C1: Master Shipper | D1: Mode | E1: Weight | F1: Zone | G1: Status | H1: Payment | I1: Collectable Amount | J1: Forward Freight | K1: RTO Freight | L1: Reverse Charges | M1: COD Charge | N1: Gross Freight | O1: Total Freight | P1: MID | Q1: Order ID | R1: Order Value | S1: sku_code | T1: sku_count | U1: product_quantity_combined
A2: 88800000000001 | B2: Pokonut | C2: DelhiveryDirectSurfaceAC | D2: SURFACE | E2: 0.5 | F2: A | G2: Delivered | H2: PREPAID | I2: 0 | J2: 20 | K2: 0 | L2: 0 | M2: 0 | N2: 20 | O2: 23.6 | P2: MID0001 | Q2: ORD-TEST-0001 | R2: 799 | S2: TEST-SKU | T2: 1 | U2: 1
A3: 88800000000002 | B3: Pokonut | C3: DelhiveryDirectSurfaceAC | D3: SURFACE | E3: 0.5 | F3: B | G3: Delivered | H3: PREPAID | I3: 0 | J3: 22 | K3: 0 | L3: 0 | M3: 0 | N3: 22 | O3: 25.96 | P3: MID0002 | Q3: ORD-TEST-0002 | R3: 799 | S3: TEST-SKU | T3: 1 | U3: 1
A4: 88800000000003 | B4: Pokonut | C4: DelhiveryDirectSurfaceAC | D4: SURFACE | E4: 1 | F4: C | G4: Delivered | H4: PREPAID | I4: 0 | J4: 58 | K4: 0 | L4: 0 | M4: 0 | N4: 58 | O4: 68.44 | P4: MID0003 | Q4: ORD-TEST-0003 | R4: 799 | S4: TEST-SKU | T4: 1 | U4: 1
A5: 88800000000004 | B5: Pokonut | C5: DelhiveryDirectSurfaceAC | D5: SURFACE | E5: 1.5 | F5: C | G5: Delivered | H5: PREPAID | I5: 0 | J5: 87 | K5: 0 | L5: 0 | M5: 0 | N5: 87 | O5: 102.66 | P5: MID0004 | Q5: ORD-TEST-0004 | R5: 799 | S5: TEST-SKU | T5: 1 | U5: 1
A6: 88800000000005 | B6: Pokonut | C6: DelhiveryDirectSurfaceAC | D6: SURFACE | E6: 0.5 | F6: D | G6: Delivered | H6: COD | I6: 500 | J6: 33 | K6: 0 | L6: 0 | M6: 15 | N6: 48 | O6: 56.64 | P6: MID0005 | Q6: ORD-TEST-0005 | R6: 799 | S6: TEST-SKU | T6: 1 | U6: 1
A7: 88800000000006 | B7: Pokonut | C7: DelhiveryDirectSurfaceAC | D7: SURFACE | E7: 0.5 | F7: E | G7: Delivered | H7: COD | I7: 2000 | J7: 39 | K7: 0 | L7: 0 | M7: 22 | N7: 61 | O7: 71.98 | P7: MID0006 | Q7: ORD-TEST-0006 | R7: 799 | S7: TEST-SKU | T7: 1 | U7: 1
A8: 88800000000007 | B8: Pokonut | C8: DelhiveryDirectSurfaceAC | D8: SURFACE | E8: 0.5 | F8: A | G8: Delivered | H8: COD | J8: 20 | K8: 0 | L8: 0 | M8: 15 | N8: 35 | O8: 41.3 | P8: MID0007 | Q8: ORD-TEST-0007 | R8: 799 | S8: TEST-SKU | T8: 1 | U8: 1
A9: 88800000000008 | B9: Pokonut | C9: DelhiveryDirectSurfaceAC | D9: SURFACE | E9: 0.5 | F9: A | G9: RTO | H9: PREPAID | I9: 0 | J9: 20 | K9: 18 | L9: 0 | M9: 0 | N9: 38 | O9: 44.84 | P9: MID0008 | Q9: ORD-TEST-0008 | R9: 799 | S9: TEST-SKU | T9: 1 | U9: 1
A10: 88800000000009 | B10: Pokonut | C10: DelhiveryDirectSurfaceAC | D10: SURFACE | E10: 0.5 | F10: B | G10: RTO | H10: PREPAID | I10: 0 | J10: 22 | K10: 20 | L10: 0 | M10: 0 | N10: 42 | O10: 49.56 | P10: MID0009 | Q10: ORD-TEST-0009 | R10: 799 | S10: TEST-SKU | T10: 1 | U10: 1
A11: 88800000000010 | B11: Pokonut | C11: DelhiveryDirectSurfaceAC | D11: SURFACE | E11: 0.5 | F11: D | G11: RTO | H11: COD | I11: 800 | J11: 33 | K11: 31 | L11: 0 | M11: 0 | N11: 64 | O11: 75.52 | P11: MID0010 | Q11: ORD-TEST-0010 | R11: 799 | S11: TEST-SKU | T11: 1 | U11: 1
A12: 88800000000011 | B12: Pokonut | C12: DelhiveryDirectExpress | D12: AIR | E12: 0.5 | F12: B | G12: Delivered | H12: COD | I12: 1000 | J12: 29 | K12: 0 | L12: 0 | M12: 28 | N12: 57 | O12: 67.26 | P12: MID0011 | Q12: ORD-TEST-0011 | R12: 799 | S12: TEST-SKU | T12: 1 | U12: 1
A13: 88800000000012 | B13: Pokonut | C13: DelhiveryDirectExpress | D13: AIR | E13: 0.5 | F13: C | G13: Delivered | H13: COD | I13: 3000 | J13: 41 | K13: 0 | L13: 0 | M13: 45 | N13: 86 | O13: 101.48 | P13: MID0012 | Q13: ORD-TEST-0012 | R13: 799 | S13: TEST-SKU | T13: 1 | U13: 1
A14: 88800000000013 | B14: Pokonut | C14: ShadowfaxNDD-NG | D14: NDD | E14: 0.5 | F14: A | G14: Delivered | H14: PREPAID | I14: 0 | J14: 27 | K14: 0 | L14: 0 | M14: 0 | N14: 27 | O14: 31.86 | P14: MID0013 | Q14: ORD-TEST-0013 | R14: 799 | S14: TEST-SKU | T14: 1 | U14: 1
A15: 88800000000014 | B15: Pokonut | C15: ShadowfaxNDD-NG | D15: NDD | E15: 0.5 | F15: E | G15: Delivered | H15: PREPAID | I15: 0 | J15: 0 | K15: 0 | L15: 0 | M15: 0 | N15: 0 | O15: 0 | P15: MID0014 | Q15: ORD-TEST-0014 | R15: 799 | S15: TEST-SKU | T15: 1 | U15: 1
A16: 88800000000015 | B16: Pokonut | C16: DelhiveryDirectSurfaceAC | D16: SURFACE | E16: 0.5 | F16: B | G16: Delivered | H16: PREPAID | I16: 0 | J16: 22 | K16: 0 | L16: 0 | M16: 0 | N16: 22 | O16: 25.96 | P16: MID0015 | Q16: ORD-TEST-0015 | R16: 799 | S16: TEST-SKU | T16: 1 | U16: 1
A17: 88800000000016 | B17: Pokonut | C17: DelhiveryDirectSurfaceAC | D17: SURFACE | E17: 0.5 | F17: D | G17: Delivered | H17: COD | I17: 1200 | J17: 33 | K17: 0 | L17: 0 | M17: 15 | N17: 48 | O17: 56.64 | P17: MID0016 | Q17: ORD-TEST-0016 | R17: 799 | S17: TEST-SKU | T17: 1 | U17: 1
A18: 88800000000017 | B18: Pokonut | C18: BlueDart Surface | D18: SURFACE | E18: 0.5 | F18: A | G18: Delivered | H18: PREPAID | I18: 0 | J18: 24 | K18: 0 | L18: 0 | M18: 0 | N18: 24 | O18: 28.32 | P18: MID0017 | Q18: ORD-TEST-0017 | R18: 799 | S18: TEST-SKU | T18: 1 | U18: 1
A19: 88800000000018 | B19: Pokonut | C19: BlueDart Surface | D19: SURFACE | E19: 0.5 | F19: C | G19: RTO | H19: PREPAID | I19: 0 | J19: 34 | K19: 32 | L19: 0 | M19: 0 | N19: 66 | O19: 77.88 | P19: MID0018 | Q19: ORD-TEST-0018 | R19: 799 | S19: TEST-SKU | T19: 1 | U19: 1
A20: 88800000000019 | B20: Pokonut | C20: DelhiveryDirectSurfaceAC | D20: SURFACE | E20: 10 | F20: B | G20: Delivered | H20: PREPAID | I20: 0 | J20: 440 | K20: 0 | L20: 0 | M20: 0 | N20: 440 | O20: 519.2 | P20: MID0019 | Q20: ORD-TEST-0019 | R20: 799 | S20: TEST-SKU | T20: 1 | U20: 1
... A28: 88800000000027 | B28: Pokonut | C28: DelhiveryDirectSurfaceAC | D28: SURFACE | E28: 0.5 | F28: A | G28: Delivered | H28: PREPAID | I28: 0 | J28: 20 | K28: 0 | L28: 0 | M28: 0 | N28: 20 | O28: 23.6 | P28: MID0027 | Q28: ORD-TEST-0027 | R28: 799 | S28: TEST-SKU | T28: 1 | U28: 1
A29: 88800000000028 | B29: Pokonut | C29: DelhiveryDirectSurfaceAC | D29: SURFACE | E29: 0.5 | F29: B | G29: Delivered | H29: PREPAID | I29: 0 | J29: 22 | K29: 0 | L29: 0 | M29: 0 | N29: 22 | O29: 25.96 | P29: MID0028 | Q29: ORD-TEST-0028 | R29: 799 | S29: TEST-SKU | T29: 1 | U29: 1
A30: 88800000000029 | B30: Pokonut | C30: DelhiveryDirectSurfaceAC | D30: SURFACE | E30: 0.5 | F30: C | G30: Delivered | H30: PREPAID | I30: 0 | J30: 29 | K30: 0 | L30: 0 | M30: 0 | N30: 29 | O30: 34.22 | P30: MID0029 | Q30: ORD-TEST-0029 | R30: 799 | S30: TEST-SKU | T30: 1 | U30: 1
A31: 88800000000030 | B31: Pokonut | C31: DelhiveryDirectSurfaceAC | D31: SURFACE | E31: 0.5 | F31: A | G31: Cancelled | H31: PREPAID | I31: 0 | J31: 20 | K31: 0 | L31: 0 | M31: 0 | N31: 20 | O31: 23.6 | P31: MID0030 | Q31: ORD-TEST-0030 | R31: 799 | S31: TEST-SKU | T31: 1 | U31: 1
A32: 88800000000031 | B32: Pokonut | C32: DelhiveryDirectSurfaceAC | D32: SURFACE | E32: 0.5 | F32: A | G32: Delivered | H32: PREPAID | I32: 0 | J32: 20 | K32: 0 | L32: 0 | M32: 0 | N32: 20 | O32: 23.6 | P32: MID0031 | Q32: ORD-TEST-0031 | R32: 799 | S32: TEST-SKU | T32: 1 | U32: 1
A33: 88800000000032 | B33: Pokonut | C33: DelhiveryDirectSurfaceAC | D33: SURFACE | E33: 0.5 | F33: B | G33: Delivered | H33: PREPAID | I33: 0 | J33: 22 | K33: 0 | L33: 0 | M33: 0 | N33: 22 | O33: 35.96 | P33: MID0032 | Q33: ORD-TEST-0032 | R33: 799 | S33: TEST-SKU | T33: 1 | U33: 1
A34: 88800000000033 | B34: Pokonut | C34: DelhiveryDirectSurfaceAC | D34: SURFACE | E34: 0.5 | F34: D | G34: Delivered | H34: PREPAID | I34: 0 | J34: 33 | K34: 0 | L34: 0 | M34: 0 | N34: 33 | O34: 88.94 | P34: MID0033 | Q34: ORD-TEST-0033 | R34: 799 | S34: TEST-SKU | T34: 1 | U34: 1
A35: 88800000000034 | B35: Pokonut | C35: DelhiveryDirectSurfaceAC | D35: SURFACE | E35: 0.5 | F35: C | G35: Delivered | H35: PREPAID | I35: 0 | J35: 29 | K35: 0 | L35: 0 | M35: 0 | N35: 29 | O35: 24.22 | P35: MID0034 | Q35: ORD-TEST-0034 | R35: 799 | S35: TEST-SKU | T35: 1 | U35: 1
A36: 88800000000035 | B36: Pokonut | C36: DelhiveryDirectSurfaceAC | D36: SURFACE | E36: 0.5 | F36: A | G36: Delivered | H36: PREPAID | I36: 0 | J36: 20 | K36: 0 | L36: 0 | M36: 0 | N36: 20 | O36: 24.61 | P36: MID0035 | Q36: ORD-TEST-0035 | R36: 799 | S36: TEST-SKU | T36: 1 | U36: 1
A37: 88800000000036 | B37: Pokonut | C37: DelhiveryDirectSurfaceAC | D37: SURFACE | E37: 0.5 | F37: A | G37: Delivered | H37: PREPAID | I37: 0 | J37: 20 | K37: 0 | L37: 0 | M37: 0 | N37: 20 | P37: MID0036 | Q37: ORD-TEST-0036 | R37: 799 | S37: TEST-SKU | T37: 1 | U37: 1
A38: 88800000000037 | B38: Pokonut | C38: DelhiveryDirectSurfaceAC | D38: SURFACE | E38: 0.5 | F38: B | G38: Delivered | H38: COD | I38: 1000 | J38: 22 | K38: 0 | L38: 0 | M38: 0 | N38: 22 | O38: 25.96 | P38: MID0037 | Q38: ORD-TEST-0037 | R38: 799 | S38: TEST-SKU | T38: 1 | U38: 1
A39: 88800000000038 | B39: Pokonut | C39: DelhiveryDirectSurfaceAC | D39: SURFACE | E39: 0.5 | F39: C | G39: RTO | H39: COD | I39: 1000 | J39: 29 | K39: 27 | L39: 0 | M39: 15 | N39: 71 | O39: 83.78 | P39: MID0038 | Q39: ORD-TEST-0038 | R39: 799 | S39: TEST-SKU | T39: 1 | U39: 1
A40: 88800000000039 | B40: Pokonut | C40: DelhiveryDirectSurfaceAC | D40: SURFACE | E40: 0.5 | F40: D | G40: RTO | H40: PREPAID | I40: 0 | J40: 33 | K40: 0 | L40: 0 | M40: 0 | N40: 33 | O40: 38.94 | P40: MID0039 | Q40: ORD-TEST-0039 | R40: 799 | S40: TEST-SKU | T40: 1 | U40: 1
A41: 88800000000040 | B41: Pokonut | C41: DelhiveryDirectSurfaceAC | D41: SURFACE | E41: 0.5 | F41: B | G41: Delivered | H41: PREPAID | I41: 0 | J41: 22 | K41: 0 | L41: 0 | M41: 0 | N41: 22 | O41: 22 | P41: MID0040 | Q41: ORD-TEST-0040 | R41: 799 | S41: TEST-SKU | T41: 1 | U41: 1
A42: 88800000000041 | B42: Pokonut | C42: DelhiveryDirectSurfaceAC | D42: SURFACE | E42: 0.5 | F42: A | G42: Delivered | H42: COD | I42: 500 | J42: 20 | K42: 0 | L42: 0 | M42: 15 | N42: 35 | O42: 41.3 | P42: MID0041 | Q42: ORD-TEST-0041 | R42: 799 | S42: TEST-SKU | T42: 1 | U42: 1
A43: 88800000000042 | B43: Pokonut | C43: DelhiveryDirectSurfaceAC | D43: SURFACE | E43: 0.5 | F43: B | G43: Delivered | H43: PREPAID | I43: 500 | J43: 22 | K43: 0 | L43: 0 | M43: 0 | N43: 22 | O43: 25.96 | P43: MID0042 | Q43: ORD-TEST-0042 | R43: 799 | S43: TEST-SKU | T43: 1 | U43: 1
A44: 88800000000043 | B44: Pokonut | C44: DelhiveryDirectSurfaceAC | D44: SURFACE | E44: 0.5 | F44: A | G44: Delivered | H44: PREPAID | I44: 0 | J44: 20 | K44: 0 | L44: 0 | M44: 0 | N44: 20 | O44: 23.6 | P44: MID0043 | Q44: ORD-TEST-0043 | R44: 799 | S44: TEST-SKU | T44: 1 | U44: 1
A45: 88800000000044 | B45: Pokonut | C45: DelhiveryDirectSurfaceAC | D45: SURFACE | E45: 0.5 | F45: B | G45: RTO | H45: PREPAID | I45: 0 | J45: 22 | K45: 0 | L45: 0 | M45: 0 | N45: 22 | O45: 25.96 | P45: MID0044 | Q45: ORD-TEST-0044 | R45: 799 | S45: TEST-SKU | T45: 1 | U45: 1
A46: 88800000000045 | B46: Pokonut | C46: DelhiveryDirectSurfaceAC | D46: SURFACE | E46: 0.5 | F46: C | G46: Delivered | H46: PREPAID | I46: 0 | J46: 29 | K46: 27 | L46: 0 | M46: 0 | N46: 56 | O46: 66.08 | P46: MID0045 | Q46: ORD-TEST-0045 | R46: 799 | S46: TEST-SKU | T46: 1 | U46: 1
A47: 88800000000046 | B47: Pokonut | C47: DelhiveryDirectSurfaceAC | D47: SURFACE | E47: 0.5 | F47: A | G47: Delivered | H47: PREPAID | I47: 0 | J47: 29 | K47: 0 | L47: 0 | M47: 0 | N47: 29 | O47: 34.22 | P47: MID0046 | Q47: ORD-TEST-0046 | R47: 799 | S47: TEST-SKU | T47: 1 | U47: 1
...

Sheet Expected Results
A1: Test ID | B1: AWB | C1: Scenario | D1: What it checks | E1: Load shipment file first | F1: Expected result | G1: Expected calc freight (Rs) | H1: MIS total freight (Rs) | I1: Expected difference (calc - MIS) | J1: Expected class | K1: Expected claim (Rs) | L1: Notes | M1: Actual result (you fill) | N1: Pass / Fail
A2: MTC-001 | B2: 88800000000001 | C2: Surface zone A, prepaid, 0.5 kg, billed correctly | D2: Basic happy path | E2: Shipment_Test_Data.xlsx | F2: MATCHED | G2: 23.6 | H2: =IF(ISBLANK(MIS!O2),0,MIS!O2) | I2: =IF(G2="","",ROUND(G2-H2,2)) | J2: =IF(G2="","",IF(I2<-1,"Overcharged",IF(I2>1,"Undercharged","Within tolerance")))
A3: MTC-002 | B3: 88800000000002 | C3: API weight 100 g vs MIS 0.5 kg (same slab) | D3: Weight compared by slab, not raw kg | E3: Shipment_Test_Data.xlsx | F3: MATCHED | G3: 25.96 | H3: =IF(ISBLANK(MIS!O3),0,MIS!O3) | I3: =IF(G3="","",ROUND(G3-H3,2)) | J3: =IF(G3="","",IF(I3<-1,"Overcharged",IF(I3>1,"Undercharged","Within tolerance")))
A4: MTC-003 | B4: 88800000000003 | C4: Exactly 1.0 kg (2 slabs) | D4: Slab rounding at an exact multiple | E4: Shipment_Test_Data.xlsx | F4: MATCHED | G4: 68.44 | H4: =IF(ISBLANK(MIS!O4),0,MIS!O4) | I4: =IF(G4="","",ROUND(G4-H4,2)) | J4: =IF(G4="","",IF(I4<-1,"Overcharged",IF(I4>1,"Undercharged","Within tolerance")))
A5: MTC-004 | B5: 88800000000004 | C5: Weight 1.01 kg (3 slabs) | D5: Slab rounding just over a slab | E5: Shipment_Test_Data.xlsx | F5: MATCHED | G5: 102.66 | H5: =IF(ISBLANK(MIS!O5),0,MIS!O5) | I5: =IF(G5="","",ROUND(G5-H5,2)) | J5: =IF(G5="","",IF(I5<-1,"Overcharged",IF(I5>1,"Undercharged","Within tolerance")))
A6: MTC-005 | B6: 88800000000005 | C6: COD 500 - flat Rs 15 wins over 1.1% | D6: COD = MAX(flat, %) | E6: Shipment_Test_Data.xlsx | F6: MATCHED | G6: 56.64 | H6: =IF(ISBLANK(MIS!O6),0,MIS!O6) | I6: =IF(G6="","",ROUND(G6-H6,2)) | J6: =IF(G6="","",IF(I6<-1,"Overcharged",IF(I6>1,"Undercharged","Within tolerance")))
A7: MTC-006 | B7: 88800000000006 | C7: COD 2000 - 1.1% (Rs 22) wins over flat | D7: COD = MAX(flat, %) | E7: Shipment_Test_Data.xlsx | F7: MATCHED | G7: 71.98 | H7: =IF(ISBLANK(MIS!O7),0,MIS!O7) | I7: =IF(G7="","",ROUND(G7-H7,2)) | J7: =IF(G7="","",IF(I7<-1,"Overcharged",IF(I7>1,"Undercharged","Within tolerance")))
A8: MTC-007 | B8: 88800000000007 | C8: COD amount left blank on a COD order | D8: Blank collectable amount treated as 0 | E8: Shipment_Test_Data.xlsx | F8: MATCHED | G8: 41.3 | H8: =IF(ISBLANK(MIS!O8),0,MIS!O8) | I8: =IF(G8="","",ROUND(G8-H8,2)) | J8: =IF(G8="","",IF(I8<-1,"Overcharged",IF(I8>1,"Undercharged","Within tolerance"))) | L8: Collectable Amount cell is empty; COD charge falls back to the flat fee.
A9: MTC-008 | B9: 88800000000008 | C9: RTO delivered, prepaid (forward + RTO freight) | D9: RTO adds RTO freight | E9: Shipment_Test_Data.xlsx | F9: MATCHED | G9: 44.84 | H9: =IF(ISBLANK(MIS!O9),0,MIS!O9) | I9: =IF(G9="","",ROUND(G9-H9,2)) | J9: =IF(G9="","",IF(I9<-1,"Overcharged",IF(I9>1,"Undercharged","Within tolerance")))
A10: MTC-009 | B10: 88800000000009 | C10: Return delivered treated as RTO | D10: return_delivered counts as RTO | E10: Shipment_Test_Data.xlsx | F10: MATCHED | G10: 49.56 | H10: =IF(ISBLANK(MIS!O10),0,MIS!O10) | I10: =IF(G10="","",ROUND(G10-H10,2)) | J10: =IF(G10="","",IF(I10<-1,"Overcharged",IF(I10>1,"Undercharged","Within tolerance")))
A11: MTC-010 | B11: 88800000000010 | C11: COD order that ended in RTO - no COD charge | D11: No COD charge on RTO | E11: Shipment_Test_Data.xlsx | F11: MATCHED | G11: 75.52 | H11: =IF(ISBLANK(MIS!O11),0,MIS!O11) | I11: =IF(G11="","",ROUND(G11-H11,2)) | J11: =IF(G11="","",IF(I11<-1,"Overcharged",IF(I11>1,"Undercharged","Within tolerance")))
A12: MTC-011 | B12: 88800000000011 | C12: Air mode, COD 1000 (flat Rs 28) | D12: Air rates and COD | E12: Shipment_Test_Data.xlsx | F12: MATCHED | G12: 67.26 | H12: =IF(ISBLANK(MIS!O12),0,MIS!O12) | I12: =IF(G12="","",ROUND(G12-H12,2)) | J12: =IF(G12="","",IF(I12<-1,"Overcharged",IF(I12>1,"Undercharged","Within tolerance")))
A13: MTC-012 | B13: 88800000000012 | C13: Air mode, COD 3000 (1.5% = Rs 45) | D13: Air COD percentage | E13: Shipment_Test_Data.xlsx | F13: MATCHED | G13: 101.48 | H13: =IF(ISBLANK(MIS!O13),0,MIS!O13) | I13: =IF(G13="","",ROUND(G13-H13,2)) | J13: =IF(G13="","",IF(I13<-1,"Overcharged",IF(I13>1,"Undercharged","Within tolerance")))
A14: MTC-013 | B14: 88800000000013 | C14: NDD mode zone A | D14: NDD rates | E14: Shipment_Test_Data.xlsx | F14: MATCHED | G14: 31.86 | H14: =IF(ISBLANK(MIS!O14),0,MIS!O14) | I14: =IF(G14="","",ROUND(G14-H14,2)) | J14: =IF(G14="","",IF(I14<-1,"Overcharged",IF(I14>1,"Undercharged","Within tolerance")))
A15: MTC-014 | B15: 88800000000014 | C15: NDD mode zone E (rate is 0 in the card) | D15: Zero-rate lane | E15: Shipment_Test_Data.xlsx | F15: MATCHED | G15: 0 | H15: =IF(ISBLANK(MIS!O15),0,MIS!O15) | I15: =IF(G15="","",ROUND(G15-H15,2)) | J15: =IF(G15="","",IF(I15<-1,"Overcharged",IF(I15>1,"Undercharged","Within tolerance"))) | L15: Card has rate 0 for NDD zone E, so calculated freight is 0. Confirm the business intends this.
A16: MTC-015 | B16: 88800000000015 | C16: Pinjore hub, zone B | D16: Pickup 134102 uses the Pinjore map | E16: Shipment_Test_Data.xlsx | F16: MATCHED | G16: 25.96 | H16: =IF(ISBLANK(MIS!O16),0,MIS!O16) | I16: =IF(G16="","",ROUND(G16-H16,2)) | J16: =IF(G16="","",IF(I16<-1,"Overcharged",IF(I16>1,"Undercharged","Within tolerance")))
A17: MTC-016 | B17: 88800000000016 | C17: Pinjore hub, zone D, COD | D17: Pinjore + COD | E17: Shipment_Test_Data.xlsx | F17: MATCHED | G17: 56.64 | H17: =IF(ISBLANK(MIS!O17),0,MIS!O17) | I17: =IF(G17="","",ROUND(G17-H17,2)) | J17: =IF(G17="","",IF(I17<-1,"Overcharged",IF(I17>1,"Undercharged","Within tolerance")))
A18: MTC-017 | B18: 88800000000017 | C18: Bluedart courier surface zone A | D18: BLUEDART rate group | E18: Shipment_Test_Data.xlsx | F18: MATCHED | G18: 28.32 | H18: =IF(ISBLANK(MIS!O18),0,MIS!O18) | I18: =IF(G18="","",ROUND(G18-H18,2)) | J18: =IF(G18="","",IF(I18<-1,"Overcharged",IF(I18>1,"Undercharged","Within tolerance")))
A19: MTC-018 | B19: 88800000000018 | C19: Bluedart RTO zone C | D19: BLUEDART RTO rates | E19: Shipment_Test_Data.xlsx | F19: MATCHED | G19: 77.88 | H19: =IF(ISBLANK(MIS!O19),0,MIS!O19) | I19: =IF(G19="","",ROUND(G19-H19,2)) | J19: =IF(G19="","",IF(I19<-1,"Overcharged",IF(I19>1,"Undercharged","Within tolerance")))
A20: MTC-019 | B20: 88800000000019 | C20: Heavy parcel 10 kg (20 slabs) | D20: Large weights | E20: Shipment_Test_Data.xlsx | F20: MATCHED | G20: 519.2 | H20: =IF(ISBLANK(MIS!O20),0,MIS!O20) | I20: =IF(G20="","",ROUND(G20-H20,2)) | J20: =IF(G20="","",IF(I20<-1,"Overcharged",IF(I20>1,"Undercharged","Within tolerance")))
A21: MTC-020 | B21: 88800000000020 | C21: Tiny weight: raw value 2 (= 2 grams, NOT 2 kg) | D21: Weights are always grams | E21: Shipment_Test_Data.xlsx | F21: MATCHED | G21: 23.6 | H21: =IF(ISBLANK(MIS!O21),0,MIS!O21) | I21: =IF(G21="","",ROUND(G21-H21,2)) | J21: =IF(G21="","",IF(I21<-1,"Overcharged",IF(I21>1,"Undercharged","Within tolerance"))) | L21: Regression: raw weight 2 must become 0.002 kg (1 slab), not 2 kg.
A22: MTC-021 | B22: 88800000000021 | C22: Tiny weight: raw value 10 | D22: Weights are always grams | E22: Shipment_Test_Data.xlsx | F22: MATCHED | G22: 25.96 | H22: =IF(ISBLANK(MIS!O22),0,MIS!O22) | I22: =IF(G22="","",ROUND(G22-H22,2)) | J22: =IF(G22="","",IF(I22<-1,"Overcharged",IF(I22>1,"Undercharged","Within tolerance")))
A23: MTC-022 | B23: 88800000000022 | C23: Weight exactly 500 g | D23: Boundary: 500 g = 1 slab | E23: Shipment_Test_Data.xlsx | F23: MATCHED | G23: 23.6 | H23: =IF(ISBLANK(MIS!O23),0,MIS!O23) | I23: =IF(G23="","",ROUND(G23-H23,2)) | J23: =IF(G23="","",IF(I23<-1,"Overcharged",IF(I23>1,"Undercharged","Within tolerance")))
A24: MTC-023 | B24: 88800000000023 | C24: MIS total is Rs 0.80 above calculated | D24: Inside Rs 1 tolerance | E24: Shipment_Test_Data.xlsx | F24: MATCHED | G24: 23.6 | H24: =IF(ISBLANK(MIS!O24),0,MIS!O24) | I24: =IF(G24="","",ROUND(G24-H24,2)) | J24: =IF(G24="","",IF(I24<-1,"Overcharged",IF(I24>1,"Undercharged","Within tolerance"))) | L24: Delta = -0.80, within tolerance so still MATCHED.
A25: MTC-024 | B25: 88800000000024 | C25: MIS total is exactly Rs 1.00 above calculated | D25: Tolerance boundary (not more than 1) | E25: Shipment_Test_Data.xlsx | F25: MATCHED | G25: 25.96 | H25: =IF(ISBLANK(MIS!O25),0,MIS!O25) | I25: =IF(G25="","",ROUND(G25-H25,2)) | J25: =IF(G25="","",IF(I25<-1,"Overcharged",IF(I25>1,"Undercharged","Within tolerance"))) | L25: Delta = -1.00 is not greater than 1, so MATCHED.
A26: MTC-025 | B26: 88800000000025 | C26: MIS zone written in lowercase | D26: Zone is upper-cased on read | E26: Shipment_Test_Data.xlsx | F26: MATCHED | G26: 34.22 | H26: =IF(ISBLANK(MIS!O26),0,MIS!O26) | I26: =IF(G26="","",ROUND(G26-H26,2)) | J26: =IF(G26="","",IF(I26<-1,"Overcharged",IF(I26>1,"Undercharged","Within tolerance")))
A27: MTC-026 | B27: 88800000000026 | C27: Payment written as 'cod' / 'Prepaid' | D27: Payment compared ignoring case | E27: Shipment_Test_Data.xlsx | F27: MATCHED | G27: 41.3 | H27: =IF(ISBLANK(MIS!O27),0,MIS!O27) | I27: =IF(G27="","",ROUND(G27-H27,2)) | J27: =IF(G27="","",IF(I27<-1,"Overcharged",IF(I27>1,"Undercharged","Within tolerance")))
A28: MTC-027 | B28: 88800000000027 | C28: Shipment status in capitals 'DELIVERED' | D28: Status compared ignoring case | E28: Shipment_Test_Data.xlsx | F28: MATCHED | G28: 23.6 | H28: =IF(ISBLANK(MIS!O28),0,MIS!O28) | I28: =IF(G28="","",ROUND(G28-H28,2)) | J28: =IF(G28="","",IF(I28<-1,"Overcharged",IF(I28>1,"Undercharged","Within tolerance")))
A29: MTC-028 | B29: 88800000000028 | C29: AWB stored as a number in the MIS sheet | D29: Numeric AWB matches text AWB | E29: Shipment_Test_Data.xlsx | F29: MATCHED | G29: 25.96 | H29: =IF(ISBLANK(MIS!O29),0,MIS!O29) | I29: =IF(G29="","",ROUND(G29-H29,2)) | J29: =IF(G29="","",IF(I29<-1,"Overcharged",IF(I29>1,"Undercharged","Within tolerance")))
A30: MTC-029 | B30: 88800000000029 | C30: AWB with leading/trailing spaces in MIS | D30: AWB trimming | E30: Shipment_Test_Data.xlsx | F30: MATCHED | G30: 34.22 | H30: =IF(ISBLANK(MIS!O30),0,MIS!O30) | I30: =IF(G30="","",ROUND(G30-H30,2)) | J30: =IF(G30="","",IF(I30<-1,"Overcharged",IF(I30>1,"Undercharged","Within tolerance"))) | L30: The app trims spaces around the AWB, so this row should match the shipment normally.
A31: MTC-030 | B31: 88800000000030 | C31: MIS Cancelled vs shipment cancelled | D31: Non-delivered statuses compared by group | E31: Shipment_Test_Data.xlsx | F31: MATCHED | G31: 23.6 | H31: =IF(ISBLANK(MIS!O31),0,MIS!O31) | I31: =IF(G31="","",ROUND(G31-H31,2)) | J31: =IF(G31="","",IF(I31<-1,"Overcharged",IF(I31>1,"Undercharged","Within tolerance"))) | L31: Status matches by group; freight is still calculated.
A32: MTC-031 | B32: 88800000000031 | C32: Shipment file has the AWB twice (last row wins) | D32: Duplicate AWB inside shipment file | E32: Shipment_Test_Data.xlsx | F32: MATCHED | G32: 23.6 | H32: =IF(ISBLANK(MIS!O32),0,MIS!O32) | I32: =IF(G32="","",ROUND(G32-H32,2)) | J32: =IF(G32="","",IF(I32<-1,"Overcharged",IF(I32>1,"Undercharged","Within tolerance"))) | L32: Shipment file lists this AWB first as in_transit then as delivered. The last row should win.
A33: MTC-032 | B33: 88800000000032 | C33: Kwikship overcharged by Rs 10 | D33: Overcharge | E33: Shipment_Test_Data.xlsx | F33: FREIGHT_MISMATCH | G33: 25.96 | H33: =IF(ISBLANK(MIS!O33),0,MIS!O33) | I33: =IF(G33="","",ROUND(G33-H33,2)) | J33: =IF(G33="","",IF(I33<-1,"Overcharged",IF(I33>1,"Undercharged","Within tolerance")))
A34: MTC-033 | B34: 88800000000033 | C34: Kwikship overcharged by Rs 50 | D34: Overcharge (larger) | E34: Shipment_Test_Data.xlsx | F34: FREIGHT_MISMATCH | G34: 38.94 | H34: =IF(ISBLANK(MIS!O34),0,MIS!O34) | I34: =IF(G34="","",ROUND(G34-H34,2)) | J34: =IF(G34="","",IF(I34<-1,"Overcharged",IF(I34>1,"Undercharged","Within tolerance")))
A35: MTC-034 | B35: 88800000000034 | C35: Kwikship undercharged by Rs 10 | D35: Undercharge | E35: Shipment_Test_Data.xlsx | F35: FREIGHT_MISMATCH | G35: 34.22 | H35: =IF(ISBLANK(MIS!O35),0,MIS!O35) | I35: =IF(G35="","",ROUND(G35-H35,2)) | J35: =IF(G35="","",IF(I35<-1,"Overcharged",IF(I35>1,"Undercharged","Within tolerance")))
A36: MTC-035 | B36: 88800000000035 | C36: Rs 1.01 over calculated (just past tolerance) | D36: Tolerance boundary | E36: Shipment_Test_Data.xlsx | F36: FREIGHT_MISMATCH | G36: 23.6 | H36: =IF(ISBLANK(MIS!O36),0,MIS!O36) | I36: =IF(G36="","",ROUND(G36-H36,2)) | J36: =IF(G36="","",IF(I36<-1,"Overcharged",IF(I36>1,"Undercharged","Within tolerance")))
A37: MTC-036 | B37: 88800000000036 | C37: MIS Total Freight left blank | D37: Blank total treated as 0 | E37: Shipment_Test_Data.xlsx | F37: FREIGHT_MISMATCH | G37: 23.6 | H37: =IF(ISBLANK(MIS!O37),0,MIS!O37) | I37: =IF(G37="","",ROUND(G37-H37,2)) | J37: =IF(G37="","",IF(I37<-1,"Overcharged",IF(I37>1,"Undercharged","Within tolerance"))) | L37: Whole calculated freight shows as undercharged.
A38: MTC-037 | B38: 88800000000037 | C38: Kwikship forgot the COD charge | D38: Missing COD charge | E38: Shipment_Test_Data.xlsx | F38: FREIGHT_MISMATCH | G38: 43.66 | H38: =IF(ISBLANK(MIS!O38),0,MIS!O38) | I38: =IF(G38="","",ROUND(G38-H38,2)) | J38: =IF(G38="","",IF(I38<-1,"Overcharged",IF(I38>1,"Undercharged","Within tolerance")))
A39: MTC-038 | B39: 88800000000038 | C39: Kwikship charged COD on an RTO order | D39: COD on RTO overcharge | E39: Shipment_Test_Data.xlsx | F39: FREIGHT_MISMATCH | G39: 66.08 | H39: =IF(ISBLANK(MIS!O39),0,MIS!O39) | I39: =IF(G39="","",ROUND(G39-H39,2)) | J39: =IF(G39="","",IF(I39<-1,"Overcharged",IF(I39>1,"Undercharged","Within tolerance")))
A40: MTC-039 | B40: 88800000000039 | C40: Kwikship left out the RTO charge | D40: Missing RTO freight | E40: Shipment_Test_Data.xlsx | F40: FREIGHT_MISMATCH | G40: 75.52 | H40: =IF(ISBLANK(MIS!O40),0,MIS!O40) | I40: =IF(G40="","",ROUND(G40-H40,2)) | J40: =IF(G40="","",IF(I40<-1,"Overcharged",IF(I40>1,"Undercharged","Within tolerance")))
...

Sheet Guide
A1: MIS test file - how to use
A2: What this is | B2: 76 MIS rows, one scenario per row, built in the same column layout as a real Kwikship MIS file. Each row has a known correct outcome listed on the 'Expected Results' sheet.
A3: Step 1 | B3: In the app open 'Upload Shipment Data' and upload Shipment_Test_Data.xlsx. Then upload Shipment_Test_Data_AddressPickup.xlsx (3 rows that test pincode-from-address).
A4: Step 2 | B4: Make sure the rate card and both zone maps are loaded (Bangalore 560076 and Pinjore 134102). The expected values below assume the standard Schedule B card.
A5: Step 3 | B5: Open 'MIS Upload' and upload THIS file. Only the first sheet ('MIS') is read; the other sheets are ignored by the app.
A6: Step 4 | B6: Click 'Run reconciliation'. Open the run and search each AWB (or use the filters).
A7: Step 5 | B7: On 'Expected Results' type what the app shows into 'Actual result' and choose Pass or Fail. Compare the totals below with the run's summary tiles.
A8: Why it works | B8: All AWBs start with 888 so they will not clash with real shipments. Pincodes and zones were taken from your live zone maps. Kwikship 'billed' amounts on the MIS sheet were calculated with the rate card and then changed on purpose in the error scenarios.
A9: Cleanup | B9: Test data stays in the database. Delete the test run from Reconciliation Runs when done. The 888... AWBs can stay in shipment data; they never appear in real MIS files.
A11: Expected totals for this run
A12: Result | B12: Expected count | C12: Actual (from app) | D12: Match?
A13: MATCHED | B13: =COUNTIF('Expected Results'!$F$2:$F$77,A13) | D13: =IF(C13="","",IF(C13=B13,"OK","Different"))
A14: FREIGHT_MISMATCH | B14: =COUNTIF('Expected Results'!$F$2:$F$77,A14) | D14: =IF(C14="","",IF(C14=B14,"OK","Different"))
A15: PAYMENT_MISMATCH | B15: =COUNTIF('Expected Results'!$F$2:$F$77,A15) | D15: =IF(C15="","",IF(C15=B15,"OK","Different"))
A16: STATUS_MISMATCH | B16: =COUNTIF('Expected Results'!$F$2:$F$77,A16) | D16: =IF(C16="","",IF(C16=B16,"OK","Different"))
A17: ZONE_MISMATCH | B17: =COUNTIF('Expected Results'!$F$2:$F$77,A17) | D17: =IF(C17="","",IF(C17=B17,"OK","Different"))
A18: WEIGHT_MISMATCH | B18: =COUNTIF('Expected Results'!$F$2:$F$77,A18) | D18: =IF(C18="","",IF(C18=B18,"OK","Different"))
A19: LOST | B19: =COUNTIF('Expected Results'!$F$2:$F$77,A19) | D19: =IF(C19="","",IF(C19=B19,"OK","Different"))
A20: NO_API_DATA | B20: =COUNTIF('Expected Results'!$F$2:$F$77,A20) | D20: =IF(C20="","",IF(C20=B20,"OK","Different"))
A21: ZONE_NOT_FOUND | B21: =COUNTIF('Expected Results'!$F$2:$F$77,A21) | D21: =IF(C21="","",IF(C21=B21,"OK","Different"))
A22: RATE_NOT_FOUND | B22: =COUNTIF('Expected Results'!$F$2:$F$77,A22) | D22: =IF(C22="","",IF(C22=B22,"OK","Different"))
A23: TOTAL rows | B23: =SUM(B13:B22) | C23: =IF(COUNT(C13:C22)=0,"",SUM(C13:C22))
A25: Money and claims
A26: Measure | B26: Expected | C26: Actual (from app) | D26: Match?
A27: Matched (summary tile) | B27: =B13 | D27: =IF(C27="","",IF(ROUND(C27-B27,2)=0,"OK","Different"))
A28: Mismatched (summary tile - includes the LOST rows) | B28: =SUM(B13:B22)-B13-B20 | D28: =IF(C28="","",IF(ROUND(C28-B28,2)=0,"OK","Different"))
A29: No API data (summary tile) | B29: =B20 | D29: =IF(C29="","",IF(ROUND(C29-B29,2)=0,"OK","Different"))
A30: Overcharged rows (Kwikship owes you) - count | B30: =COUNTIFS('Expected Results'!$J$2:$J$77,"Overcharged") | D30: =IF(C30="","",IF(ROUND(C30-B30,2)=0,"OK","Different"))
A31: Overcharged amount (Rs) | B31: =-SUMIFS('Expected Results'!$I$2:$I$77,'Expected Results'!$J$2:$J$77,"Overcharged") | D31: =IF(C31="","",IF(ROUND(C31-B31,2)=0,"OK","Different"))
A32: Undercharged rows (you may owe) - count | B32: =COUNTIF('Expected Results'!$J$2:$J$77,"Undercharged") | D32: =IF(C32="","",IF(ROUND(C32-B32,2)=0,"OK","Different"))
A33: Undercharged amount (Rs) | B33: =SUMIFS('Expected Results'!$I$2:$I$77,'Expected Results'!$J$2:$J$77,"Undercharged") | D33: =IF(C33="","",IF(ROUND(C33-B33,2)=0,"OK","Different"))
A34: Lost rows | B34: =COUNTIF('Expected Results'!$F$2:$F$77,"LOST") | D34: =IF(C34="","",IF(ROUND(C34-B34,2)=0,"OK","Different"))
A35: Total claimable (Rs) | B35: =SUM('Expected Results'!$K$2:$K$77) | D35: =IF(C35="","",IF(ROUND(C35-B35,2)=0,"OK","Different"))
A36: Note: the money figures only count rows the app can price. A real run compares to these only if this is the only MIS you reconcile for the test.
A38: Rate card used (blue = input)
A39: Group / mode / type | B39: A | C39: B | D39: C | E39: D | F39: E
A40: ALL / SURFACE / Forward | B40: 20 | C40: 22 | D40: 29 | E40: 33 | F40: 39
A41: ALL / SURFACE / RTO | B41: 18 | C41: 20 | D41: 27 | E41: 31 | F41: 37
A42: ALL / AIR / Forward | B42: 25 | C42: 29 | D42: 41 | E42: 50 | F42: 80
A43: ALL / AIR / RTO | B43: 25 | C43: 29 | D43: 41 | E43: 50 | F43: 80
...
